<?xml version="1.0"?>
<!-- ======================================================================== -->
<!-- |          Flexiv Rizon 10 (with blurred dynamic parameters)           | -->
<!-- ======================================================================== -->
<robot name="Rizon10">
    <joint name="joint1" type="revolute">
        <parent link="base_link" />
        <child link="link1" />
        <origin rpy="0.0 0.0 -3.141592653589793" xyz="0.0 0.0 0.21" />
        <axis xyz="0 0 1" />
        <limit effort="261" lower="-2.8798" upper="2.8798" velocity="1.7453" />
        <safety_controller k_position="100.0" k_velocity="40.0" soft_lower_limit="-2.7925"
            soft_upper_limit="2.7925" />
    </joint>
    <joint name="joint2" type="revolute">
        <parent link="link1" />
        <child link="link2" />
        <origin rpy="0.0 0.0 0.0" xyz="0.0 0.0675 0.24" />
        <axis xyz="0 1 0" />
        <limit effort="261" lower="-2.7576" upper="2.7576" velocity="1.7453" />
        <safety_controller k_position="100.0" k_velocity="40.0" soft_lower_limit="-2.6704"
            soft_upper_limit="2.6704" />
    </joint>
    <joint name="joint3" type="revolute">
        <parent link="link2" />
        <child link="link3" />
        <origin rpy="0.0 0.0 0.0" xyz="0.0 0.0625 0.2275" />
        <axis xyz="0 0 1" />
        <limit effort="123" lower="-2.8798" upper="2.8798" velocity="2.0944" />
        <safety_controller k_position="100.0" k_velocity="40.0" soft_lower_limit="-2.7925"
            soft_upper_limit="2.7925" />
    </joint>
    <joint name="joint4" type="revolute">
        <parent link="link3" />
        <child link="link4" />
        <origin rpy="0.0 0.0 -3.141592653589793" xyz="0.0 -0.0625 0.2225" />
        <axis xyz="0 1 0" />
        <limit effort="123" lower="-2.7925" upper="2.7925" velocity="2.0944" />
        <safety_controller k_position="100.0" k_velocity="40.0" soft_lower_limit="-2.7053"
            soft_upper_limit="2.7053" />
    </joint>
    <joint name="joint5" type="revolute">
        <parent link="link4" />
        <child link="link5" />
        <origin rpy="0.0 0.0 -3.141592653589793" xyz="0.0 0.0575 0.205" />
        <axis xyz="0 0 1" />
        <limit effort="57" lower="-3.0543" upper="3.0543" velocity="3.8397" />
        <safety_controller k_position="100.0" k_velocity="40.0" soft_lower_limit="-2.9671"
            soft_upper_limit="2.9671" />
    </joint>
    <joint name="joint6" type="revolute">
        <parent link="link5" />
        <child link="link6" />
        <origin rpy="0.0 0.0 0.0" xyz="0.0 0.03 0.19" />
        <axis xyz="0 1 0" />
        <limit effort="57" lower="-1.4835" upper="4.6251" velocity="3.8397" />
        <safety_controller k_position="100.0" k_velocity="40.0" soft_lower_limit="-1.3963"
            soft_upper_limit="4.5379" />
    </joint>
    <joint name="joint7" type="revolute">
        <parent link="link6" />
        <child link="link7" />
        <origin rpy="0.0 -1.5707963478683205 0.0" xyz="-0.015 0.073 0.11" />
        <axis xyz="0 0 1" />
        <limit effort="57" lower="-3.0543" upper="3.0543" velocity="3.8397" />
        <safety_controller k_position="100.0" k_velocity="40.0" soft_lower_limit="-2.9671"
            soft_upper_limit="2.9671" />
    </joint>
    <joint name="link7_to_flange" type="fixed">
        <parent link="link7" />
        <child link="flange" />
        <origin rpy="0.0 0.0 -3.141592653589793" xyz="0.0 0.0 0.081" />
    </joint>

    <link name="base_link">
        <inertial>
            <mass value="8.1" />
            <origin rpy="0 0 0" xyz="0.0 -0.0 0.12" />
            <inertia ixx="0.06" ixy="0.0" ixz="-0.0" iyy="0.06" iyz="0.0" izz="0.03" />
        </inertial>
        <visual name="shell">
            <origin rpy="0 0 0" xyz="0 0 0" />
            <geometry>
                <mesh filename="package://meshes/Rizon10/visual/link0.obj" />
            </geometry>
        </visual>
        <collision name="convex_mesh">
            <origin rpy="0 0 0" xyz="0 0 0" />
            <geometry>
                <mesh filename="package://meshes/Rizon10/collision/link0.stl" />
            </geometry>
        </collision>
        <workspace>
            <origin rpy="0 0 0" xyz="0 0 0.450" />
            <geometry>
                <sphere radius="0.955" />
            </geometry>
        </workspace>
    </link>
    <link name="link1">
        <inertial>
            <mass value="9.5" />
            <origin rpy="0 0 0" xyz="0.0 0.02 0.16" />
            <inertia ixx="0.12" ixy="0.0" ixz="-0.0" iyy="0.11" iyz="0.01" izz="0.04" />
        </inertial>
        <visual name="shell">
            <origin rpy="0 0 0" xyz="0 0 0" />
            <geometry>
                <mesh filename="package://meshes/Rizon10/visual/link1.obj" />
            </geometry>
        </visual>
        <visual name="ring">
            <origin rpy="0 0 0" xyz="0 0 -0.0025" />
            <geometry>
                <mesh filename="package://meshes/Rizon10/visual/ring.obj" scale="0.079 0.079 0.002" />
            </geometry>
        </visual>
        <collision name="convex_mesh">
            <origin rpy="0 0 0" xyz="0 0 0" />
            <geometry>
                <mesh filename="package://meshes/Rizon10/collision/link1.stl" />
            </geometry>
        </collision>
    </link>
    <link name="link2">
        <inertial>
            <mass value="6.6" />
            <origin rpy="0 0 0" xyz="-0.0 0.06 0.09" />
            <inertia ixx="0.08" ixy="0.0" ixz="0.0" iyy="0.08" iyz="0.0" izz="0.01" />
        </inertial>
        <visual name="shell">
            <origin rpy="0 0 0" xyz="0 0 0" />
            <geometry>
                <mesh filename="package://meshes/Rizon10/visual/link2.obj" />
            </geometry>
        </visual>
        <visual name="ring">
            <origin rpy="1.5707963 0 0" xyz="0 -0.0025 0" />
            <geometry>
                <mesh filename="package://meshes/Rizon10/visual/ring.obj" scale="0.079 0.079 0.002" />
            </geometry>
        </visual>
        <collision name="convex_mesh">
            <origin rpy="0 0 0" xyz="0 0 0" />
            <geometry>
                <mesh filename="package://meshes/Rizon10/collision/link2.stl" />
            </geometry>
        </collision>
    </link>
    <link name="link3">
        <inertial>
            <mass value="4.5" />
            <origin rpy="0 0 0" xyz="-0.0 -0.02 0.17" />
            <inertia ixx="0.04" ixy="0.0" ixz="-0.0" iyy="0.03" iyz="-0.01" izz="0.01" />
        </inertial>
        <visual name="shell">
            <origin rpy="0 0 0" xyz="0 0 0" />
            <geometry>
                <mesh filename="package://meshes/Rizon10/visual/link3.obj" />
            </geometry>
        </visual>
        <visual name="ring">
            <origin rpy="0 0 0" xyz="0 0 -0.0025" />
            <geometry>
                <mesh filename="package://meshes/Rizon10/visual/ring.obj" scale="0.062 0.062 0.002" />
            </geometry>
        </visual>
        <collision name="convex_mesh">
            <origin rpy="0 0 0" xyz="0 0 0" />
            <geometry>
                <mesh filename="package://meshes/Rizon10/collision/link3.stl" />
            </geometry>
        </collision>
    </link>
    <link name="link4">
        <inertial>
            <mass value="3.2" />
            <origin rpy="0 0 0" xyz="0.0 0.05 0.09" />
            <inertia ixx="0.03" ixy="0.0" ixz="0.0" iyy="0.03" iyz="0.0" izz="0.0" />
        </inertial>
        <visual name="shell">
            <origin rpy="0 0 0" xyz="0 0 0" />
            <geometry>
                <mesh filename="package://meshes/Rizon10/visual/link4.obj" />
            </geometry>
        </visual>
        <visual name="ring">
            <origin rpy="1.5707963 0 0" xyz="0 -0.0025 0" />
            <geometry>
                <mesh filename="package://meshes/Rizon10/visual/ring.obj" scale="0.062 0.062 0.002" />
            </geometry>
        </visual>
        <collision name="convex_mesh">
            <origin rpy="0 0 0" xyz="0 0 0" />
            <geometry>
                <mesh filename="package://meshes/Rizon10/collision/link4.stl" />
            </geometry>
        </collision>
    </link>
    <link name="link5">
        <inertial>
            <mass value="2.4" />
            <origin rpy="0 0 0" xyz="0.0 0.0 0.14" />
            <inertia ixx="0.01" ixy="0.0" ixz="0.0" iyy="0.01" iyz="0.0" izz="0.0" />
        </inertial>
        <visual name="shell">
            <origin rpy="0 0 0" xyz="0 0 0" />
            <geometry>
                <mesh filename="package://meshes/Rizon10/visual/link5.obj" />
            </geometry>
        </visual>
        <visual name="ring">
            <origin rpy="0 0 0" xyz="0 0 -0.0025" />
            <geometry>
                <mesh filename="package://meshes/Rizon10/visual/ring.obj" scale="0.051 0.051 0.002" />
            </geometry>
        </visual>
        <collision name="convex_mesh">
            <origin rpy="0 0 0" xyz="0 0 0" />
            <geometry>
                <mesh filename="package://meshes/Rizon10/collision/link5.stl" />
            </geometry>
        </collision>
    </link>
    <link name="link6">
        <inertial>
            <mass value="2.3" />
            <origin rpy="0 0 0" xyz="0.02 0.06 0.07" />
            <inertia ixx="0.01" ixy="0.0" ixz="0.0" iyy="0.01" iyz="0.0" izz="0.0" />
        </inertial>
        <visual name="shell">
            <origin rpy="0 0 0" xyz="0 0 0" />
            <geometry>
                <mesh filename="package://meshes/Rizon10/visual/link6.obj" />
            </geometry>
        </visual>
        <visual name="ring">
            <origin rpy="1.5707963 0 0" xyz="0 -0.0025 0" />
            <geometry>
                <mesh filename="package://meshes/Rizon10/visual/ring.obj" scale="0.051 0.051 0.002" />
            </geometry>
        </visual>
        <collision name="convex_mesh">
            <origin rpy="0 0 0" xyz="0 0 0" />
            <geometry>
                <mesh filename="package://meshes/Rizon10/collision/link6.stl" />
            </geometry>
        </collision>
    </link>
    <link name="link7">
        <inertial>
            <mass value="0.8" />
            <origin rpy="0 0 0" xyz="0.0 0.0 0.03" />
            <inertia ixx="0.0" ixy="0.0" ixz="0.0" iyy="0.0" iyz="0.0" izz="0.0" />
        </inertial>
        <visual name="shell">
            <origin rpy="0 0 0" xyz="0 0 0" />
            <geometry>
                <mesh filename="package://meshes/Rizon10/visual/link7.obj" />
            </geometry>
        </visual>
        <visual name="ring">
            <origin rpy="0 0 0" xyz="0 0 -0.0025" />
            <geometry>
                <mesh filename="package://meshes/Rizon10/visual/ring.obj" scale="0.051 0.051 0.002" />
            </geometry>
        </visual>
        <collision name="convex_mesh">
            <origin rpy="0 0 0" xyz="0 0 0" />
            <geometry>
                <mesh filename="package://meshes/Rizon10/collision/link7.stl" />
            </geometry>
        </collision>
    </link>
    <link name="flange">
        <inertial>
            <mass value="0.0" />
            <origin rpy="0 0 0" xyz="0.0 0.0 0.0" />
            <inertia ixx="0.0" ixy="0.0" ixz="0.0" iyy="0.0" iyz="0.0" izz="0.0" />
        </inertial>
    </link>
</robot>