<?xml version="1.0"?>
<!-- ======================================================================== -->
<!-- | Flexiv Rizon4 Arm (Approximated dynamic parameters)                  | -->
<!-- ======================================================================== -->
<robot name="flexiv_rizon4">
  <!-- ============================ Link Configuration ===================== -->
  <link name="world" />
  <!-- ============ base link =========== -->
  <link name="base">
    <inertial>
      <mass value="3.6" />
      <origin rpy="0 0 0" xyz="0.0 0.0 0.09" />
      <inertia ixx="0.02" iyy="0.02" izz="0.009" ixy="0" ixz="0" iyz="0" />
    </inertial>
    <visual>
      <origin rpy="0 0 0" xyz="0 0 0" />
      <geometry>
        <mesh filename="meshes/visual/link0.dae" />
      </geometry>
    </visual>
    <collision>
      <origin xyz="0 0 0" rpy="0 0 0" />
      <geometry>
        <mesh filename="meshes/collision/link0.stl" />
      </geometry>
    </collision>
  </link>
  <!-- ============ link 1 ============= -->
  <link name="link1">
    <inertial>
      <mass value="3.6" />
      <origin rpy="0 0 0" xyz="0.0 0.005 0.15" />
      <inertia ixx="0.027" iyy="0.027" izz="0.007" ixy="0" ixz="0" iyz="0.0016" />
    </inertial>
    <visual>
      <origin rpy="0 0 0" xyz="0 0 0" />
      <geometry>
        <mesh filename="meshes/visual/link1.dae" />
      </geometry>
    </visual>
    <collision>
      <origin xyz="0 0 0" rpy="0 0 0" />
      <geometry>
        <mesh filename="meshes/collision/link1.stl" />
      </geometry>
    </collision>
  </link>
  <!-- ============ link 2 ============= -->
  <link name="link2">
    <inertial>
      <mass value="2.7" />
      <origin rpy="0 0 0" xyz="0.0 0.036 0.1" />
      <inertia ixx="0.023" iyy="0.023" izz="0.004" ixy="0" ixz="0" iyz="0.0003" />
    </inertial>
    <visual>
      <origin rpy="0 0 0" xyz="0 0 0" />
      <geometry>
        <mesh filename="meshes/visual/link2.dae" />
      </geometry>
    </visual>
    <collision>
      <origin xyz="0 0 0" rpy="0 0 0" />
      <geometry>
        <mesh filename="meshes/collision/link2.stl" />
      </geometry>
    </collision>
  </link>
  <!-- ============ link 3 ============= -->
  <link name="link3">
    <inertial>
      <mass value="2.5" />
      <origin rpy="0 0 0" xyz="-0.011 0.0 0.13" />
      <inertia ixx="0.015" iyy="0.015" izz="0.004" ixy="0.0" ixz="-0.002" iyz="0.0" />
    </inertial>
    <visual>
      <origin rpy="0 0 0" xyz="0 0 0" />
      <geometry>
        <mesh filename="meshes/visual/link3.dae" />
      </geometry>
    </visual>
    <collision>
      <origin xyz="0 0 0" rpy="0 0 0" />
      <geometry>
        <mesh filename="meshes/collision/link3.stl" />
      </geometry>
    </collision>
  </link>
  <!-- ============ link 4 ============= -->
  <link name="link4">
    <inertial>
      <mass value="2.45" />
      <origin rpy="0 0 0" xyz="-0.012 0.03 0.097" />
      <inertia ixx="0.02" iyy="0.02" izz="0.003" ixy="0.0" ixz="-0.002" iyz="-0.001" />
    </inertial>
    <visual>
      <origin rpy="0 0 0" xyz="0 0 0" />
      <geometry>
        <mesh filename="meshes/visual/link4.dae" />
      </geometry>
    </visual>
    <collision>
      <origin xyz="0 0 0" rpy="0 0 0" />
      <geometry>
        <mesh filename="meshes/collision/link4.stl" />
      </geometry>
    </collision>
  </link>
  <!-- ============ link 5 ============= -->
  <link name="link5">
    <inertial>
      <mass value="2.4" />
      <origin rpy="0 0 0" xyz="0.0 0.0 0.13" />
      <inertia ixx="0.015" iyy="0.014" izz="0.004" ixy="0" ixz="0.0" iyz="0.0008" />
    </inertial>
    <visual>
      <origin rpy="0 0 0" xyz="0 0 0" />
      <geometry>
        <mesh filename="meshes/visual/link5.dae" />
      </geometry>
    </visual>
    <collision>
      <origin xyz="0 0 0" rpy="0 0 0" />
      <geometry>
        <mesh filename="meshes/collision/link5.stl" />
      </geometry>
    </collision>
  </link>
  <!-- ============ link 6 ============= -->
  <link name="link6">
    <inertial>
      <mass value="2.2" />
      <origin rpy="0 0 0" xyz="0.009 0.055 0.066" />
      <inertia ixx="0.009" iyy="0.009" izz="0.004" ixy="0" ixz="0" iyz="0.002" />
    </inertial>
    <visual>
      <origin rpy="0 0 0" xyz="0 0 0" />
      <geometry>
        <mesh filename="meshes/visual/link6.dae" />
      </geometry>
    </visual>
    <collision>
      <origin xyz="0 0 0" rpy="0 0 0" />
      <geometry>
        <mesh filename="meshes/collision/link6.stl" />
      </geometry>
    </collision>
  </link>

  <!-- ============ link 7 ============= -->
  <link name="link7">
    <inertial>
      <mass value="0.94" />
      <origin rpy="0 0 0" xyz="0.0 0.0 0.025" />
      <inertia ixx="0.0012" iyy="0.0012" izz="0.0011" ixy="0" ixz="0" iyz="0" />
    </inertial>
    <visual>
      <origin rpy="0 0 0" xyz="0 0 0" />
      <geometry>
        <mesh filename="meshes/visual/link7.dae" />
      </geometry>
    </visual>
    <collision>
      <origin xyz="0 0 0" rpy="0 0 0" />
      <geometry>
        <mesh filename="meshes/collision/link7.stl" />
      </geometry>
    </collision>
  </link>

  <!-- ============ flange ============= -->
  <link name="flange">
    <inertial>
      <mass value="0.0" />
      <origin rpy="0 0 0" xyz="0 0 0" />
      <inertia ixx="0.0" iyy="0.0" izz="0.0" ixy="0.0" ixz="0.0" iyz="0.0" />
    </inertial>
  </link>

  <!-- ========================= Joint Configuration ======================= -->
  <!-- ============ joint 0 =============== -->
  <joint name="joint0" type="fixed">
    <origin rpy="0 0 0" xyz="0 0 0" />
    <parent link="world" />
    <child link="base" />
  </joint>

  <!-- ============ joint 1 =============== -->
  <joint name="joint1" type="revolute">
    <origin rpy="0 0 3.1415927" xyz="0.0 0.0 0.155" />
    <axis xyz="0 0 1" />
    <limit effort="123" lower="-2.7925" upper="2.7925" velocity="2.0944" />
    <dynamics damping="0.1" />
    <parent link="base" />
    <child link="link1" />
  </joint>

  <!-- ============ joint 2 =============== -->
  <joint name="joint2" type="revolute">
    <origin rpy="0 0 0" xyz="0.0 0.03 0.210" />
    <axis xyz="0 1 0" />
    <limit effort="123" lower="-2.2689" upper="2.2689" velocity="2.0944" />
    <dynamics damping="0.1" />
    <parent link="link1" />
    <child link="link2" />
  </joint>

  <!-- ============ joint 3 =============== -->
  <joint name="joint3" type="revolute">
    <origin rpy="0 0 0" xyz="0.0 0.035 0.205" />
    <axis xyz="0 0 1" />
    <limit effort="64" lower="-2.9671" upper="2.9671" velocity="2.4435" />
    <dynamics damping="0.1" />
    <parent link="link2" />
    <child link="link3" />
  </joint>

  <!-- ============ joint 4 =============== -->
  <joint name="joint4" type="revolute">
    <origin rpy="0 0 -3.1415927" xyz="-0.02 -0.03 0.19" />
    <axis xyz="0 1 0" />
    <limit effort="64" lower="-1.8675" upper="2.6878" velocity="2.4435" />
    <dynamics damping="0.1" />
    <parent link="link3" />
    <child link="link4" />
  </joint>

  <!-- ============ joint 5 =============== -->
  <joint name="joint5" type="revolute">
    <origin rpy="0 0 -3.1415927" xyz="-0.02 0.025 0.195" />
    <axis xyz="0 0 1" />
    <limit effort="39" lower="-2.9671" upper="2.9671" velocity="4.8869" />
    <dynamics damping="0.1" />
    <parent link="link4" />
    <child link="link5" />
  </joint>

  <!-- ============ joint 6 =============== -->
  <joint name="joint6" type="revolute">
    <origin rpy="0 0 0" xyz="0.0 0.03 0.19" />
    <axis xyz="0 1 0" />
    <limit effort="39" lower="-1.3963" upper="4.5379" velocity="4.8869" />
    <dynamics damping="0.1" />
    <parent link="link5" />
    <child link="link6" />
  </joint>

  <!-- ============ joint 7 =============== -->
  <joint name="joint7" type="revolute">
    <origin rpy="0 -1.5707963 0" xyz="-0.055 0.070 0.11" />
    <axis xyz="0 0 1" />
    <limit effort="39" lower="-2.9671" upper="2.9671" velocity="4.8869" />
    <dynamics damping="0.1" />
    <parent link="link6" />
    <child link="link7" />
  </joint>
  <!-- ============ joint flange =============== -->
  <joint name="jointF" type="fixed">
    <origin rpy="0 0 -3.1415927" xyz="0.0 0.0 0.074" />
    <parent link="link7" />
    <child link="flange" />
  </joint>
</robot>